f10>: Failed to establish a new connection: [Errno 111] Connection refused

uring handling of the above exception, another exception occurred:

Traceback (most recent call last):
  File "/data/hyou37/anaconda3/envs/tinyml/lib/python3.7/site-packages/requests/adapters.py", l
ine 497, in send
    chunked=chunked,
  File "/data/hyou37/anaconda3/envs/tinyml/lib/python3.7/site-packages/urllib3/connectionpool.p
y", line 799, in urlopen
    method, url, error=e, _pool=self, _stacktrace=sys.exc_info()[2]
  File "/data/hyou37/anaconda3/envs/tinyml/lib/python3.7/site-packages/urllib3/util/retry.py",
line 592, in increment
    raise MaxRetryError(_pool, url, error or ResponseError(cause))
urllib3.exceptions.MaxRetryError: HTTPConnectionPool(host='localhost', port=9000): Max retries
exceeded with url: /api/v1/nni/experiment (Caused by NewConnectionError('<urllib3.connection.HT
TPConnection object at 0x7f2b9447ff10>: Failed to establish a new connection: [Errno 111] Conne
ction refused'))

During handling of the above exception, another exception occurred:

Traceback (most recent call last):
  File "/data/hyou37/anaconda3/envs/tinyml/lib/python3.7/site-packages/nni/experiment/experimen
t.py", line 143, in _stop_impl
    rest.delete(self.port, '/experiment', self.url_prefix)
  File "/data/hyou37/anaconda3/envs/tinyml/lib/python3.7/site-packages/nni/experiment/rest.py",
 line 52, in delete
    request('delete', port, api, prefix=prefix)
  File "/data/hyou37/anaconda3/envs/tinyml/lib/python3.7/site-packages/nni/experiment/rest.py",
 line 31, in request
    resp = requests.request(method, url, timeout=timeout)
  File "/data/hyou37/anaconda3/envs/tinyml/lib/python3.7/site-packages/requests/api.py", line 5
9, in request
    return session.request(method=method, url=url, **kwargs)
  File "/data/hyou37/anaconda3/envs/tinyml/lib/python3.7/site-packages/requests/sessions.py", l
ine 589, in request
    resp = self.send(prep, **send_kwargs)
  File "/data/hyou37/anaconda3/envs/tinyml/lib/python3.7/site-packages/requests/sessions.py", l
ine 703, in send
    r = adapter.send(request, **kwargs)
  File "/data/hyou37/anaconda3/envs/tinyml/lib/python3.7/site-packages/requests/adapters.py", l
ine 519, in send
    raise ConnectionError(e, request=request)
requests.exceptions.ConnectionError: HTTPConnectionPool(host='localhost', port=9000): Max retri
es exceeded with url: /api/v1/nni/experiment (Caused by NewConnectionError('<urllib3.connection
.HTTPConnection object at 0x7f2b9447ff10>: Failed to establish a new connection: [Errno 111] Co
nnection refused'))
[2023-09-15 01:08:29] WARNING: Cannot gracefully stop experiment, killing NNI process...
[2023-09-15 01:08:29] Experiment stopped

[2023-09-15 01:08:30] Stopping experiment, please wait...
[2023-09-15 01:08:30] Experiment stopped
(tinyml) hyou37@eic-gt-gpu1:/data/hyou37/TinyML-Contest-Solution/Training$ python nni_nas.py
[2023-09-15 01:12:32] Creating experiment, Experiment ID: 9a078gwk
[2023-09-15 01:12:32] Starting web server...
[2023-09-15 01:12:33] Setting up...
[2023-09-15 01:12:33] Web portal URLs: http://127.0.0.1:9000 http://130.207.125.90:9000 http://
172.17.0.1:9000
node:events:504
      throw er; // Unhandled 'error' event
      ^

Error: tuner_command_channel: Tuner closed connection
    at WebSocket.handleWsClose (/data/hyou37/anaconda3/envs/tinyml/lib/python3.7/site-packages/
nni_node/core/tuner_command_channel/websocket_channel.js:83:26)
    at WebSocket.emit (node:events:538:35)
    at WebSocket.emitClose (/data/hyou37/anaconda3/envs/tinyml/lib/python3.7/site-packages/nni_
node/node_modules/express-ws/node_modules/ws/lib/websocket.js:246:10)
    at Socket.socketOnClose (/data/hyou37/anaconda3/envs/tinyml/lib/python3.7/site-packages/nni
_node/node_modules/express-ws/node_modules/ws/lib/websocket.js:1127:15)
    at Socket.emit (node:events:526:28)
    at TCP.<anonymous> (node:net:687:12)
Emitted 'error' event at:
    at WebSocketChannelImpl.handleError (/data/hyou37/anaconda3/envs/tinyml/lib/python3.7/site-
packages/nni_node/core/tuner_command_channel/websocket_channel.js:135:22)
    at WebSocket.handleWsClose (/data/hyou37/anaconda3/envs/tinyml/lib/python3.7/site-packages/
nni_node/core/tuner_command_channel/websocket_channel.js:83:14)
    at WebSocket.emit (node:events:538:35)
    [... lines matching original stack trace ...]
    at TCP.<anonymous> (node:net:687:12)
Thrown at:
    at handleWsClose (/data/hyou37/anaconda3/envs/tinyml/lib/python3.7/site-packages/nni_node/c
ore/tuner_command_channel/websocket_channel.js:83:26)
    at emit (node:events:538:35)
    at emitClose (/data/hyou37/anaconda3/envs/tinyml/lib/python3.7/site-packages/nni_node/node_
modules/express-ws/node_modules/ws/lib/websocket.js:246:10)
    at socketOnClose (/data/hyou37/anaconda3/envs/tinyml/lib/python3.7/site-packages/nni_node/n
ode_modules/express-ws/node_modules/ws/lib/websocket.js:1127:15)
    at emit (node:events:526:28)
    at node:net:687:12
Traceback (most recent call last):
  File "/data/hyou37/anaconda3/envs/tinyml/lib/python3.7/site-packages/urllib3/connection.py",
line 175, in _new_conn
    (self._dns_host, self.port), self.timeout, **extra_kw
  File "/data/hyou37/anaconda3/envs/tinyml/lib/python3.7/site-packages/urllib3/util/connection.
py", line 95, in create_connection
    raise err
  File "/data/hyou37/anaconda3/envs/tinyml/lib/python3.7/site-packages/urllib3/util/connection.
py", line 85, in create_connection
    sock.connect(sa)
ConnectionRefusedError: [Errno 111] Connection refused

During handling of the above exception, another exception occurred:

Traceback (most recent call last):
  File "/data/hyou37/anaconda3/envs/tinyml/lib/python3.7/site-packages/urllib3/connectionpool.p
y", line 721, in urlopen
    chunked=chunked,
  File "/data/hyou37/anaconda3/envs/tinyml/lib/python3.7/site-packages/urllib3/connectionpool.p
y", line 415, in _make_request
    conn.request(method, url, **httplib_request_kw)
  File "/data/hyou37/anaconda3/envs/tinyml/lib/python3.7/site-packages/urllib3/connection.py",
line 244, in request
    super(HTTPConnection, self).request(method, url, body=body, headers=headers)
  File "/data/hyou37/anaconda3/envs/tinyml/lib/python3.7/http/client.py", line 1281, in request
    self._send_request(method, url, body, headers, encode_chunked)
  File "/data/hyou37/anaconda3/envs/tinyml/lib/python3.7/http/client.py", line 1327, in _send_r
equest
    self.endheaders(body, encode_chunked=encode_chunked)
  File "/data/hyou37/anaconda3/envs/tinyml/lib/python3.7/http/client.py", line 1276, in endhead
ers
    self._send_output(message_body, encode_chunked=encode_chunked)
  File "/data/hyou37/anaconda3/envs/tinyml/lib/python3.7/http/client.py", line 1036, in _send_o
utput
    self.send(msg)
  File "/data/hyou37/anaconda3/envs/tinyml/lib/python3.7/http/client.py", line 976, in send
    self.connect()
  File "/data/hyou37/anaconda3/envs/tinyml/lib/python3.7/site-packages/urllib3/connection.py",
line 205, in connect
    conn = self._new_conn()
  File "/data/hyou37/anaconda3/envs/tinyml/lib/python3.7/site-packages/urllib3/connection.py",
line 187, in _new_conn
    self, "Failed to establish a new connection: %s" % e
urllib3.exceptions.NewConnectionError: <urllib3.connection.HTTPConnection object at 0x7f0e7168a
f10>: Failed to establish a new connection: [Errno 111] Connection refused

During handling of the above exception, another exception occurred:

Traceback (most recent call last):
  File "/data/hyou37/anaconda3/envs/tinyml/lib/python3.7/site-packages/requests/adapters.py", l
ine 497, in send
    chunked=chunked,
  File "/data/hyou37/anaconda3/envs/tinyml/lib/python3.7/site-packages/urllib3/connectionpool.p
y", line 799, in urlopen
    method, url, error=e, _pool=self, _stacktrace=sys.exc_info()[2]
  File "/data/hyou37/anaconda3/envs/tinyml/lib/python3.7/site-packages/urllib3/util/retry.py",
line 592, in increment
    raise MaxRetryError(_pool, url, error or ResponseError(cause))
urllib3.exceptions.MaxRetryError: HTTPConnectionPool(host='localhost', port=9000): Max retries
exceeded with url: /api/v1/nni/check-status (Caused by NewConnectionError('<urllib3.connection.
HTTPConnection object at 0x7f0e7168af10>: Failed to establish a new connection: [Errno 111] Con
nection refused'))

During handling of the above exception, another exception occurred:

Traceback (most recent call last):
  File "nni_nas.py", line 84, in <module>
    experiment.run(port=9000)
  File "/data/hyou37/anaconda3/envs/tinyml/lib/python3.7/site-packages/nni/experiment/experimen
t.py", line 183, in run
    self._wait_completion()
  File "/data/hyou37/anaconda3/envs/tinyml/lib/python3.7/site-packages/nni/experiment/experimen
t.py", line 163, in _wait_completion
    status = self.get_status()
  File "/data/hyou37/anaconda3/envs/tinyml/lib/python3.7/site-packages/nni/experiment/experimen
t.py", line 283, in get_status
    resp = rest.get(self.port, '/check-status', self.url_prefix)
  File "/data/hyou37/anaconda3/envs/tinyml/lib/python3.7/site-packages/nni/experiment/rest.py",
 line 43, in get
    return request('get', port, api, prefix=prefix)
  File "/data/hyou37/anaconda3/envs/tinyml/lib/python3.7/site-packages/nni/experiment/rest.py",
 line 31, in request
    resp = requests.request(method, url, timeout=timeout)
  File "/data/hyou37/anaconda3/envs/tinyml/lib/python3.7/site-packages/requests/api.py", line 5
9, in request
    return session.request(method=method, url=url, **kwargs)
  File "/data/hyou37/anaconda3/envs/tinyml/lib/python3.7/site-packages/requests/sessions.py", l
ine 589, in request
    resp = self.send(prep, **send_kwargs)
  File "/data/hyou37/anaconda3/envs/tinyml/lib/python3.7/site-packages/requests/sessions.py", l
ine 703, in send
    r = adapter.send(request, **kwargs)
  File "/data/hyou37/anaconda3/envs/tinyml/lib/python3.7/site-packages/requests/adapters.py", l
ine 519, in send
    raise ConnectionError(e, request=request)
requests.exceptions.ConnectionError: HTTPConnectionPool(host='localhost', port=9000): Max retri
es exceeded with url: /api/v1/nni/check-status (Caused by NewConnectionError('<urllib3.connecti
on.HTTPConnection object at 0x7f0e7168af10>: Failed to establish a new connection: [Errno 111]
Connection refused'))
[2023-09-15 01:25:34] Stopping experiment, please wait...
[2023-09-15 01:25:34] ERROR: HTTPConnectionPool(host='localhost', port=9000): Max retries excee
ded with url: /api/v1/nni/experiment (Caused by NewConnectionError('<urllib3.connection.HTTPCon
nection object at 0x7f0e81832bd0>: Failed to establish a new connection: [Errno 111] Connection
 refused'))
Traceback (most recent call last):
  File "/data/hyou37/anaconda3/envs/tinyml/lib/python3.7/site-packages/urllib3/connection.py",
line 175, in _new_conn
    (self._dns_host, self.port), self.timeout, **extra_kw
  File "/data/hyou37/anaconda3/envs/tinyml/lib/python3.7/site-packages/urllib3/util/connection.
py", line 95, in create_connection
    raise err
  File "/data/hyou37/anaconda3/envs/tinyml/lib/python3.7/site-packages/urllib3/util/connection.
py", line 85, in create_connection
    sock.connect(sa)
ConnectionRefusedError: [Errno 111] Connection refused

During handling of the above exception, another exception occurred:

Traceback (most recent call last):
  File "/data/hyou37/anaconda3/envs/tinyml/lib/python3.7/site-packages/urllib3/connectionpool.p
y", line 721, in urlopen
    chunked=chunked,
  File "/data/hyou37/anaconda3/envs/tinyml/lib/python3.7/site-packages/urllib3/connectionpool.p
y", line 415, in _make_request
    conn.request(method, url, **httplib_request_kw)
  File "/data/hyou37/anaconda3/envs/tinyml/lib/python3.7/site-packages/urllib3/connection.py",
line 244, in request
    super(HTTPConnection, self).request(method, url, body=body, headers=headers)
  File "/data/hyou37/anaconda3/envs/tinyml/lib/python3.7/http/client.py", line 1281, in request
    self._send_request(method, url, body, headers, encode_chunked)
  File "/data/hyou37/anaconda3/envs/tinyml/lib/python3.7/http/client.py", line 1327, in _send_r
equest
    self.endheaders(body, encode_chunked=encode_chunked)
  File "/data/hyou37/anaconda3/envs/tinyml/lib/python3.7/http/client.py", line 1276, in endhead
ers
    self._send_output(message_body, encode_chunked=encode_chunked)
  File "/data/hyou37/anaconda3/envs/tinyml/lib/python3.7/http/client.py", line 1036, in _send_o
utput
    self.send(msg)
  File "/data/hyou37/anaconda3/envs/tinyml/lib/python3.7/http/client.py", line 976, in send
    self.connect()
  File "/data/hyou37/anaconda3/envs/tinyml/lib/python3.7/site-packages/urllib3/connection.py",
line 205, in connect
    conn = self._new_conn()
  File "/data/hyou37/anaconda3/envs/tinyml/lib/python3.7/site-packages/urllib3/connection.py",
line 187, in _new_conn
    self, "Failed to establish a new connection: %s" % e
urllib3.exceptions.NewConnectionError: <urllib3.connection.HTTPConnection object at 0x7f0e81832
bd0>: Failed to establish a new connection: [Errno 111] Connection refused

During handling of the above exception, another exception occurred:

Traceback (most recent call last):
  File "/data/hyou37/anaconda3/envs/tinyml/lib/python3.7/site-packages/requests/adapters.py", l
ine 497, in send
    chunked=chunked,
  File "/data/hyou37/anaconda3/envs/tinyml/lib/python3.7/site-packages/urllib3/connectionpool.p
y", line 799, in urlopen
    method, url, error=e, _pool=self, _stacktrace=sys.exc_info()[2]
  File "/data/hyou37/anaconda3/envs/tinyml/lib/python3.7/site-packages/urllib3/util/retry.py",
line 592, in increment
    raise MaxRetryError(_pool, url, error or ResponseError(cause))
urllib3.exceptions.MaxRetryError: HTTPConnectionPool(host='localhost', port=9000): Max retries
exceeded with url: /api/v1/nni/experiment (Caused by NewConnectionError('<urllib3.connection.HT
TPConnection object at 0x7f0e81832bd0>: Failed to establish a new connection: [Errno 111] Conne
ction refused'))

During handling of the above exception, another exception occurred:

Traceback (most recent call last):
  File "/data/hyou37/anaconda3/envs/tinyml/lib/python3.7/site-packages/nni/experiment/experimen
t.py", line 143, in _stop_impl
    rest.delete(self.port, '/experiment', self.url_prefix)
  File "/data/hyou37/anaconda3/envs/tinyml/lib/python3.7/site-packages/nni/experiment/rest.py",
 line 52, in delete
    request('delete', port, api, prefix=prefix)
  File "/data/hyou37/anaconda3/envs/tinyml/lib/python3.7/site-packages/nni/experiment/rest.py",
 line 31, in request
    resp = requests.request(method, url, timeout=timeout)
  File "/data/hyou37/anaconda3/envs/tinyml/lib/python3.7/site-packages/requests/api.py", line 5
9, in request
    return session.request(method=method, url=url, **kwargs)
  File "/data/hyou37/anaconda3/envs/tinyml/lib/python3.7/site-packages/requests/sessions.py", l
ine 589, in request
    resp = self.send(prep, **send_kwargs)
  File "/data/hyou37/anaconda3/envs/tinyml/lib/python3.7/site-packages/requests/sessions.py", l
ine 703, in send
    r = adapter.send(request, **kwargs)
  File "/data/hyou37/anaconda3/envs/tinyml/lib/python3.7/site-packages/requests/adapters.py", l
ine 519, in send
    raise ConnectionError(e, request=request)
requests.exceptions.ConnectionError: HTTPConnectionPool(host='localhost', port=9000): Max retri
es exceeded with url: /api/v1/nni/experiment (Caused by NewConnectionError('<urllib3.connection
.HTTPConnection object at 0x7f0e81832bd0>: Failed to establish a new connection: [Errno 111] Co
nnection refused'))
[2023-09-15 01:25:34] WARNING: Cannot gracefully stop experiment, killing NNI process...
[2023-09-15 01:25:34] Experiment stopped
(tinyml) hyou37@eic-gt-gpu1:/data/hyou37/TinyML-Contest-Solution/Training$ ^C
(tinyml) hyou37@eic-gt-gpu1:/data/hyou37/TinyML-Contest-Solution/Training$ python nni_nas.py
[2023-09-15 01:51:45] Creating experiment, Experiment ID: tcs5iwjl
[2023-09-15 01:51:45] Starting web server...
[2023-09-15 01:51:46] Setting up...
[2023-09-15 01:51:46] Web portal URLs: http://127.0.0.1:9000 http://130.207.125.90:9000 http://
172.17.0.1:9000
^C[2023-09-15 02:03:15] WARNING: KeyboardInterrupt detected
[2023-09-15 02:03:15] Stopping experiment, please wait...
[2023-09-15 02:03:15] Experiment stopped

[2023-09-15 02:03:16] Stopping experiment, please wait...
[2023-09-15 02:03:16] Experiment stopped
(tinyml) hyou37@eic-gt-gpu1:/data/hyou37/TinyML-Contest-Solution/Training$ python nni_nas.py
[2023-09-15 02:03:17] Creating experiment, Experiment ID: 7a903mcb
[2023-09-15 02:03:17] Starting web server...
[2023-09-15 02:03:18] Setting up...
[2023-09-15 02:03:18] Web portal URLs: http://127.0.0.1:9000 http://130.207.125.90:9000 http://
172.17.0.1:9000
^C[2023-09-15 02:18:01] WARNING: KeyboardInterrupt detected
[2023-09-15 02:18:01] Stopping experiment, please wait...
[2023-09-15 02:18:01] Experiment stopped

[2023-09-15 02:18:02] Stopping experiment, please wait...
[2023-09-15 02:18:02] Experiment stopped
(tinyml) hyou37@eic-gt-gpu1:/data/hyou37/TinyML-Contest-Solution/Training$ python nni_nas.py
[2023-09-15 02:18:04] Creating experiment, Experiment ID: 4so1yila
[2023-09-15 02:18:04] Starting web server...
[2023-09-15 02:18:05] Setting up...
[2023-09-15 02:18:05] Web portal URLs: http://127.0.0.1:9000 http://130.207.125.90:9000 http://
172.17.0.1:9000
^C[2023-09-15 02:27:59] WARNING: KeyboardInterrupt detected
[2023-09-15 02:27:59] Stopping experiment, please wait...
[2023-09-15 02:27:59] Experiment stopped

[2023-09-15 02:27:59] Stopping experiment, please wait...
[2023-09-15 02:27:59] Experiment stopped
(tinyml) hyou37@eic-gt-gpu1:/data/hyou37/TinyML-Contest-Solution/Training$ python nni_nas.py
[2023-09-15 02:28:01] Creating experiment, Experiment ID: n9cldvfp
[2023-09-15 02:28:01] Starting web server...
[2023-09-15 02:28:02] Setting up...
[2023-09-15 02:28:02] Web portal URLs: http://127.0.0.1:9000 http://130.207.125.90:9000 http://
172.17.0.1:9000
node:events:504
      throw er; // Unhandled 'error' event
      ^

Error: tuner_command_channel: Tuner closed connection
    at WebSocket.handleWsClose (/data/hyou37/anaconda3/envs/tinyml/lib/python3.7/site-packages/
nni_node/core/tuner_command_channel/websocket_channel.js:83:26)
    at WebSocket.emit (node:events:538:35)
    at WebSocket.emitClose (/data/hyou37/anaconda3/envs/tinyml/lib/python3.7/site-packages/nni_
node/node_modules/express-ws/node_modules/ws/lib/websocket.js:246:10)
    at Socket.socketOnClose (/data/hyou37/anaconda3/envs/tinyml/lib/python3.7/site-packages/nni
_node/node_modules/express-ws/node_modules/ws/lib/websocket.js:1127:15)
    at Socket.emit (node:events:526:28)
    at TCP.<anonymous> (node:net:687:12)
Emitted 'error' event at:
    at WebSocketChannelImpl.handleError (/data/hyou37/anaconda3/envs/tinyml/lib/python3.7/site-
packages/nni_node/core/tuner_command_channel/websocket_channel.js:135:22)
    at WebSocket.handleWsClose (/data/hyou37/anaconda3/envs/tinyml/lib/python3.7/site-packages/
nni_node/core/tuner_command_channel/websocket_channel.js:83:14)
    at WebSocket.emit (node:events:538:35)
    [... lines matching original stack trace ...]
    at TCP.<anonymous> (node:net:687:12)
Thrown at:
    at handleWsClose (/data/hyou37/anaconda3/envs/tinyml/lib/python3.7/site-packages/nni_node/c
ore/tuner_command_channel/websocket_channel.js:83:26)
    at emit (node:events:538:35)
    at emitClose (/data/hyou37/anaconda3/envs/tinyml/lib/python3.7/site-packages/nni_node/node_
modules/express-ws/node_modules/ws/lib/websocket.js:246:10)
    at socketOnClose (/data/hyou37/anaconda3/envs/tinyml/lib/python3.7/site-packages/nni_node/n
ode_modules/express-ws/node_modules/ws/lib/websocket.js:1127:15)
    at emit (node:events:526:28)
    at node:net:687:12
Traceback (most recent call last):
  File "/data/hyou37/anaconda3/envs/tinyml/lib/python3.7/site-packages/urllib3/connection.py",
line 175, in _new_conn
    (self._dns_host, self.port), self.timeout, **extra_kw
  File "/data/hyou37/anaconda3/envs/tinyml/lib/python3.7/site-packages/urllib3/util/connection.
py", line 95, in create_connection
    raise err
  File "/data/hyou37/anaconda3/envs/tinyml/lib/python3.7/site-packages/urllib3/util/connection.
py", line 85, in create_connection
    sock.connect(sa)
ConnectionRefusedError: [Errno 111] Connection refused

During handling of the above exception, another exception occurred:

Traceback (most recent call last):
  File "/data/hyou37/anaconda3/envs/tinyml/lib/python3.7/site-packages/urllib3/connectionpool.p
y", line 721, in urlopen
    chunked=chunked,
  File "/data/hyou37/anaconda3/envs/tinyml/lib/python3.7/site-packages/urllib3/connectionpool.p
y", line 415, in _make_request
    conn.request(method, url, **httplib_request_kw)
  File "/data/hyou37/anaconda3/envs/tinyml/lib/python3.7/site-packages/urllib3/connection.py",
line 244, in request
    super(HTTPConnection, self).request(method, url, body=body, headers=headers)
  File "/data/hyou37/anaconda3/envs/tinyml/lib/python3.7/http/client.py", line 1281, in request
    self._send_request(method, url, body, headers, encode_chunked)
  File "/data/hyou37/anaconda3/envs/tinyml/lib/python3.7/http/client.py", line 1327, in _send_r
equest
    self.endheaders(body, encode_chunked=encode_chunked)
  File "/data/hyou37/anaconda3/envs/tinyml/lib/python3.7/http/client.py", line 1276, in endhead
ers
    self._send_output(message_body, encode_chunked=encode_chunked)
  File "/data/hyou37/anaconda3/envs/tinyml/lib/python3.7/http/client.py", line 1036, in _send_o
utput
    self.send(msg)
  File "/data/hyou37/anaconda3/envs/tinyml/lib/python3.7/http/client.py", line 976, in send
    self.connect()
  File "/data/hyou37/anaconda3/envs/tinyml/lib/python3.7/site-packages/urllib3/connection.py",
line 205, in connect
    conn = self._new_conn()
  File "/data/hyou37/anaconda3/envs/tinyml/lib/python3.7/site-packages/urllib3/connection.py",
line 187, in _new_conn
    self, "Failed to establish a new connection: %s" % e
urllib3.exceptions.NewConnectionError: <urllib3.connection.HTTPConnection object at 0x7f2e0fc1e
290>: Failed to establish a new connection: [Errno 111] Connection refused

During handling of the above exception, another exception occurred:

Traceback (most recent call last):
  File "/data/hyou37/anaconda3/envs/tinyml/lib/python3.7/site-packages/requests/adapters.py", l
ine 497, in send
    chunked=chunked,
  File "/data/hyou37/anaconda3/envs/tinyml/lib/python3.7/site-packages/urllib3/connectionpool.p
y", line 799, in urlopen
    method, url, error=e, _pool=self, _stacktrace=sys.exc_info()[2]
  File "/data/hyou37/anaconda3/envs/tinyml/lib/python3.7/site-packages/urllib3/util/retry.py",
line 592, in increment
    raise MaxRetryError(_pool, url, error or ResponseError(cause))
urllib3.exceptions.MaxRetryError: HTTPConnectionPool(host='localhost', port=9000): Max retries
exceeded with url: /api/v1/nni/check-status (Caused by NewConnectionError('<urllib3.connection.
HTTPConnection object at 0x7f2e0fc1e290>: Failed to establish a new connection: [Errno 111] Con
nection refused'))

During handling of the above exception, another exception occurred:

Traceback (most recent call last):
  File "nni_nas.py", line 83, in <module>
    experiment.run(port=9000)
  File "/data/hyou37/anaconda3/envs/tinyml/lib/python3.7/site-packages/nni/experiment/experimen
t.py", line 183, in run
    self._wait_completion()
  File "/data/hyou37/anaconda3/envs/tinyml/lib/python3.7/site-packages/nni/experiment/experimen
t.py", line 163, in _wait_completion
    status = self.get_status()
  File "/data/hyou37/anaconda3/envs/tinyml/lib/python3.7/site-packages/nni/experiment/experimen
t.py", line 283, in get_status
    resp = rest.get(self.port, '/check-status', self.url_prefix)
  File "/data/hyou37/anaconda3/envs/tinyml/lib/python3.7/site-packages/nni/experiment/rest.py",
 line 43, in get
    return request('get', port, api, prefix=prefix)
  File "/data/hyou37/anaconda3/envs/tinyml/lib/python3.7/site-packages/nni/experiment/rest.py",
 line 31, in request
    resp = requests.request(method, url, timeout=timeout)
  File "/data/hyou37/anaconda3/envs/tinyml/lib/python3.7/site-packages/requests/api.py", line 5
9, in request
    return session.request(method=method, url=url, **kwargs)
  File "/data/hyou37/anaconda3/envs/tinyml/lib/python3.7/site-packages/requests/sessions.py", l
ine 589, in request
    resp = self.send(prep, **send_kwargs)
  File "/data/hyou37/anaconda3/envs/tinyml/lib/python3.7/site-packages/requests/sessions.py", l
ine 703, in send
    r = adapter.send(request, **kwargs)
  File "/data/hyou37/anaconda3/envs/tinyml/lib/python3.7/site-packages/requests/adapters.py", l
ine 519, in send
    raise ConnectionError(e, request=request)
requests.exceptions.ConnectionError: HTTPConnectionPool(host='localhost', port=9000): Max retri
es exceeded with url: /api/v1/nni/check-status (Caused by NewConnectionError('<urllib3.connecti
on.HTTPConnection object at 0x7f2e0fc1e290>: Failed to establish a new connection: [Errno 111]
Connection refused'))
[2023-09-15 02:41:13] Stopping experiment, please wait...
[2023-09-15 02:41:13] ERROR: HTTPConnectionPool(host='localhost', port=9000): Max retries excee
ded with url: /api/v1/nni/experiment (Caused by NewConnectionError('<urllib3.connection.HTTPCon
nection object at 0x7f2e1fd49a50>: Failed to establish a new connection: [Errno 111] Connection
 refused'))
Traceback (most recent call last):
  File "/data/hyou37/anaconda3/envs/tinyml/lib/python3.7/site-packages/urllib3/connection.py",
line 175, in _new_conn
    (self._dns_host, self.port), self.timeout, **extra_kw
  File "/data/hyou37/anaconda3/envs/tinyml/lib/python3.7/site-packages/urllib3/util/connection.
py", line 95, in create_connection
    raise err
  File "/data/hyou37/anaconda3/envs/tinyml/lib/python3.7/site-packages/urllib3/util/connection.
py", line 85, in create_connection
    sock.connect(sa)
ConnectionRefusedError: [Errno 111] Connection refused

During handling of the above exception, another exception occurred:

Traceback (most recent call last):
  File "/data/hyou37/anaconda3/envs/tinyml/lib/python3.7/site-packages/urllib3/connectionpool.p
y", line 721, in urlopen
    chunked=chunked,
  File "/data/hyou37/anaconda3/envs/tinyml/lib/python3.7/site-packages/urllib3/connectionpool.p
y", line 415, in _make_request
    conn.request(method, url, **httplib_request_kw)
  File "/data/hyou37/anaconda3/envs/tinyml/lib/python3.7/site-packages/urllib3/connection.py",
line 244, in request
    super(HTTPConnection, self).request(method, url, body=body, headers=headers)
  File "/data/hyou37/anaconda3/envs/tinyml/lib/python3.7/http/client.py", line 1281, in request
    self._send_request(method, url, body, headers, encode_chunked)
  File "/data/hyou37/anaconda3/envs/tinyml/lib/python3.7/http/client.py", line 1327, in _send_r
equest
    self.endheaders(body, encode_chunked=encode_chunked)
  File "/data/hyou37/anaconda3/envs/tinyml/lib/python3.7/http/client.py", line 1276, in endhead
ers
    self._send_output(message_body, encode_chunked=encode_chunked)
  File "/data/hyou37/anaconda3/envs/tinyml/lib/python3.7/http/client.py", line 1036, in _send_o
utput
    self.send(msg)
  File "/data/hyou37/anaconda3/envs/tinyml/lib/python3.7/http/client.py", line 976, in send
    self.connect()
  File "/data/hyou37/anaconda3/envs/tinyml/lib/python3.7/site-packages/urllib3/connection.py",
line 205, in connect
    conn = self._new_conn()
  File "/data/hyou37/anaconda3/envs/tinyml/lib/python3.7/site-packages/urllib3/connection.py",
line 187, in _new_conn
    self, "Failed to establish a new connection: %s" % e
urllib3.exceptions.NewConnectionError: <urllib3.connection.HTTPConnection object at 0x7f2e1fd49
a50>: Failed to establish a new connection: [Errno 111] Connection refused

During handling of the above exception, another exception occurred:

Traceback (most recent call last):
  File "/data/hyou37/anaconda3/envs/tinyml/lib/python3.7/site-packages/requests/adapters.py", l
ine 497, in send
    chunked=chunked,
  File "/data/hyou37/anaconda3/envs/tinyml/lib/python3.7/site-packages/urllib3/connectionpool.p
y", line 799, in urlopen
    method, url, error=e, _pool=self, _stacktrace=sys.exc_info()[2]
  File "/data/hyou37/anaconda3/envs/tinyml/lib/python3.7/site-packages/urllib3/util/retry.py",
line 592, in increment
    raise MaxRetryError(_pool, url, error or ResponseError(cause))
urllib3.exceptions.MaxRetryError: HTTPConnectionPool(host='localhost', port=9000): Max retries
exceeded with url: /api/v1/nni/experiment (Caused by NewConnectionError('<urllib3.connection.HT
TPConnection object at 0x7f2e1fd49a50>: Failed to establish a new connection: [Errno 111] Conne
ction refused'))

During handling of the above exception, another exception occurred:

Traceback (most recent call last):
  File "/data/hyou37/anaconda3/envs/tinyml/lib/python3.7/site-packages/nni/experiment/experimen
t.py", line 143, in _stop_impl
    rest.delete(self.port, '/experiment', self.url_prefix)
  File "/data/hyou37/anaconda3/envs/tinyml/lib/python3.7/site-packages/nni/experiment/rest.py",
 line 52, in delete
    request('delete', port, api, prefix=prefix)
  File "/data/hyou37/anaconda3/envs/tinyml/lib/python3.7/site-packages/nni/experiment/rest.py",
 line 31, in request
    resp = requests.request(method, url, timeout=timeout)
  File "/data/hyou37/anaconda3/envs/tinyml/lib/python3.7/site-packages/requests/api.py", line 5
9, in request
    return session.request(method=method, url=url, **kwargs)
  File "/data/hyou37/anaconda3/envs/tinyml/lib/python3.7/site-packages/requests/sessions.py", l
ine 589, in request
    resp = self.send(prep, **send_kwargs)
  File "/data/hyou37/anaconda3/envs/tinyml/lib/python3.7/site-packages/requests/sessions.py", l
ine 703, in send
    r = adapter.send(request, **kwargs)
  File "/data/hyou37/anaconda3/envs/tinyml/lib/python3.7/site-packages/requests/adapters.py", l
ine 519, in send
    raise ConnectionError(e, request=request)
requests.exceptions.ConnectionError: HTTPConnectionPool(host='localhost', port=9000): Max retri
es exceeded with url: /api/v1/nni/experiment (Caused by NewConnectionError('<urllib3.connection
.HTTPConnection object at 0x7f2e1fd49a50>: Failed to establish a new connection: [Errno 111] Co
nnection refused'))
[2023-09-15 02:41:13] WARNING: Cannot gracefully stop experiment, killing NNI process...
[2023-09-15 02:41:13] Experiment stopped
(tinyml) hyou37@eic-gt-gpu1:/data/hyou37/TinyML-Contest-Solution/Training$ python nni_nas.py
[2023-09-15 02:41:59] Creating experiment, Experiment ID: j4ot8dcq
[2023-09-15 02:41:59] Starting web server...
[2023-09-15 02:42:00] Setting up...
[2023-09-15 02:42:01] Web portal URLs: http://127.0.0.1:9000 http://130.207.125.90:9000 http://
172.17.0.1:9000
node:events:504
      throw er; // Unhandled 'error' event
      ^

Error: tuner_command_channel: Tuner closed connection
    at WebSocket.handleWsClose (/data/hyou37/anaconda3/envs/tinyml/lib/python3.7/site-packages/
nni_node/core/tuner_command_channel/websocket_channel.js:83:26)
    at WebSocket.emit (node:events:538:35)
    at WebSocket.emitClose (/data/hyou37/anaconda3/envs/tinyml/lib/python3.7/site-packages/nni_
node/node_modules/express-ws/node_modules/ws/lib/websocket.js:246:10)
    at Socket.socketOnClose (/data/hyou37/anaconda3/envs/tinyml/lib/python3.7/site-packages/nni
_node/node_modules/express-ws/node_modules/ws/lib/websocket.js:1127:15)
    at Socket.emit (node:events:526:28)
    at TCP.<anonymous> (node:net:687:12)
Emitted 'error' event at:
    at WebSocketChannelImpl.handleError (/data/hyou37/anaconda3/envs/tinyml/lib/python3.7/site-
packages/nni_node/core/tuner_command_channel/websocket_channel.js:135:22)
    at WebSocket.handleWsClose (/data/hyou37/anaconda3/envs/tinyml/lib/python3.7/site-packages/
nni_node/core/tuner_command_channel/websocket_channel.js:83:14)
    at WebSocket.emit (node:events:538:35)
    [... lines matching original stack trace ...]
    at TCP.<anonymous> (node:net:687:12)
Thrown at:
    at handleWsClose (/data/hyou37/anaconda3/envs/tinyml/lib/python3.7/site-packages/nni_node/c
ore/tuner_command_channel/websocket_channel.js:83:26)
    at emit (node:events:538:35)
    at emitClose (/data/hyou37/anaconda3/envs/tinyml/lib/python3.7/site-packages/nni_node/node_
modules/express-ws/node_modules/ws/lib/websocket.js:246:10)
    at socketOnClose (/data/hyou37/anaconda3/envs/tinyml/lib/python3.7/site-packages/nni_node/n
ode_modules/express-ws/node_modules/ws/lib/websocket.js:1127:15)
    at emit (node:events:526:28)
    at node:net:687:12
Traceback (most recent call last):
  File "/data/hyou37/anaconda3/envs/tinyml/lib/python3.7/site-packages/urllib3/connection.py",
line 175, in _new_conn
    (self._dns_host, self.port), self.timeout, **extra_kw
  File "/data/hyou37/anaconda3/envs/tinyml/lib/python3.7/site-packages/urllib3/util/connection.
py", line 95, in create_connection
    raise err
  File "/data/hyou37/anaconda3/envs/tinyml/lib/python3.7/site-packages/urllib3/util/connection.
py", line 85, in create_connection
    sock.connect(sa)
ConnectionRefusedError: [Errno 111] Connection refused

During handling of the above exception, another exception occurred:

Traceback (most recent call last):
  File "/data/hyou37/anaconda3/envs/tinyml/lib/python3.7/site-packages/urllib3/connectionpool.p
y", line 721, in urlopen
    chunked=chunked,
  File "/data/hyou37/anaconda3/envs/tinyml/lib/python3.7/site-packages/urllib3/connectionpool.p
y", line 415, in _make_request
    conn.request(method, url, **httplib_request_kw)
  File "/data/hyou37/anaconda3/envs/tinyml/lib/python3.7/site-packages/urllib3/connection.py",
line 244, in request
    super(HTTPConnection, self).request(method, url, body=body, headers=headers)
  File "/data/hyou37/anaconda3/envs/tinyml/lib/python3.7/http/client.py", line 1281, in request
    self._send_request(method, url, body, headers, encode_chunked)
  File "/data/hyou37/anaconda3/envs/tinyml/lib/python3.7/http/client.py", line 1327, in _send_r
equest
    self.endheaders(body, encode_chunked=encode_chunked)
  File "/data/hyou37/anaconda3/envs/tinyml/lib/python3.7/http/client.py", line 1276, in endhead
ers
    self._send_output(message_body, encode_chunked=encode_chunked)
  File "/data/hyou37/anaconda3/envs/tinyml/lib/python3.7/http/client.py", line 1036, in _send_o
utput
    self.send(msg)
  File "/data/hyou37/anaconda3/envs/tinyml/lib/python3.7/http/client.py", line 976, in send
    self.connect()
  File "/data/hyou37/anaconda3/envs/tinyml/lib/python3.7/site-packages/urllib3/connection.py",
line 205, in connect
    conn = self._new_conn()
  File "/data/hyou37/anaconda3/envs/tinyml/lib/python3.7/site-packages/urllib3/connection.py",
line 187, in _new_conn
    self, "Failed to establish a new connection: %s" % e
urllib3.exceptions.NewConnectionError: <urllib3.connection.HTTPConnection object at 0x7f42922df
490>: Failed to establish a new connection: [Errno 111] Connection refused

During handling of the above exception, another exception occurred:

Traceback (most recent call last):
  File "/data/hyou37/anaconda3/envs/tinyml/lib/python3.7/site-packages/requests/adapters.py", l
ine 497, in send
    chunked=chunked,
  File "/data/hyou37/anaconda3/envs/tinyml/lib/python3.7/site-packages/urllib3/connectionpool.p
y", line 799, in urlopen
    method, url, error=e, _pool=self, _stacktrace=sys.exc_info()[2]
  File "/data/hyou37/anaconda3/envs/tinyml/lib/python3.7/site-packages/urllib3/util/retry.py",
line 592, in increment
    raise MaxRetryError(_pool, url, error or ResponseError(cause))
urllib3.exceptions.MaxRetryError: HTTPConnectionPool(host='localhost', port=9000): Max retries
exceeded with url: /api/v1/nni/check-status (Caused by NewConnectionError('<urllib3.connection.
HTTPConnection object at 0x7f42922df490>: Failed to establish a new connection: [Errno 111] Con
nection refused'))

During handling of the above exception, another exception occurred:

Traceback (most recent call last):
  File "nni_nas.py", line 83, in <module>
    experiment.run(port=9000)
  File "/data/hyou37/anaconda3/envs/tinyml/lib/python3.7/site-packages/nni/experiment/experimen
t.py", line 183, in run
    self._wait_completion()
  File "/data/hyou37/anaconda3/envs/tinyml/lib/python3.7/site-packages/nni/experiment/experimen
t.py", line 163, in _wait_completion
    status = self.get_status()
  File "/data/hyou37/anaconda3/envs/tinyml/lib/python3.7/site-packages/nni/experiment/experimen
t.py", line 283, in get_status
    resp = rest.get(self.port, '/check-status', self.url_prefix)
  File "/data/hyou37/anaconda3/envs/tinyml/lib/python3.7/site-packages/nni/experiment/rest.py",
 line 43, in get
    return request('get', port, api, prefix=prefix)
  File "/data/hyou37/anaconda3/envs/tinyml/lib/python3.7/site-packages/nni/experiment/rest.py",
 line 31, in request
    resp = requests.request(method, url, timeout=timeout)
  File "/data/hyou37/anaconda3/envs/tinyml/lib/python3.7/site-packages/requests/api.py", line 5
9, in request
    return session.request(method=method, url=url, **kwargs)
  File "/data/hyou37/anaconda3/envs/tinyml/lib/python3.7/site-packages/requests/sessions.py", l
ine 589, in request
    resp = self.send(prep, **send_kwargs)
  File "/data/hyou37/anaconda3/envs/tinyml/lib/python3.7/site-packages/requests/sessions.py", l
ine 703, in send
    r = adapter.send(request, **kwargs)
  File "/data/hyou37/anaconda3/envs/tinyml/lib/python3.7/site-packages/requests/adapters.py", l
ine 519, in send
    raise ConnectionError(e, request=request)
requests.exceptions.ConnectionError: HTTPConnectionPool(host='localhost', port=9000): Max retri
es exceeded with url: /api/v1/nni/check-status (Caused by NewConnectionError('<urllib3.connecti
on.HTTPConnection object at 0x7f42922df490>: Failed to establish a new connection: [Errno 111]
Connection refused'))
[2023-09-15 02:55:12] Stopping experiment, please wait...
[2023-09-15 02:55:12] ERROR: HTTPConnectionPool(host='localhost', port=9000): Max retries excee
ded with url: /api/v1/nni/experiment (Caused by NewConnectionError('<urllib3.connection.HTTPCon
nection object at 0x7f42a242ea50>: Failed to establish a new connection: [Errno 111] Connection
 refused'))
Traceback (most recent call last):
  File "/data/hyou37/anaconda3/envs/tinyml/lib/python3.7/site-packages/urllib3/connection.py",
line 175, in _new_conn
    (self._dns_host, self.port), self.timeout, **extra_kw
  File "/data/hyou37/anaconda3/envs/tinyml/lib/python3.7/site-packages/urllib3/util/connection.
py", line 95, in create_connection
    raise err
  File "/data/hyou37/anaconda3/envs/tinyml/lib/python3.7/site-packages/urllib3/util/connection.
py", line 85, in create_connection
    sock.connect(sa)
ConnectionRefusedError: [Errno 111] Connection refused

During handling of the above exception, another exception occurred:

Traceback (most recent call last):
  File "/data/hyou37/anaconda3/envs/tinyml/lib/python3.7/site-packages/urllib3/connectionpool.p
y", line 721, in urlopen
    chunked=chunked,
  File "/data/hyou37/anaconda3/envs/tinyml/lib/python3.7/site-packages/urllib3/connectionpool.p
y", line 415, in _make_request
    conn.request(method, url, **httplib_request_kw)
  File "/data/hyou37/anaconda3/envs/tinyml/lib/python3.7/site-packages/urllib3/connection.py",
line 244, in request
    super(HTTPConnection, self).request(method, url, body=body, headers=headers)
  File "/data/hyou37/anaconda3/envs/tinyml/lib/python3.7/http/client.py", line 1281, in request
    self._send_request(method, url, body, headers, encode_chunked)
  File "/data/hyou37/anaconda3/envs/tinyml/lib/python3.7/http/client.py", line 1327, in _send_r
equest
    self.endheaders(body, encode_chunked=encode_chunked)
  File "/data/hyou37/anaconda3/envs/tinyml/lib/python3.7/http/client.py", line 1276, in endhead
ers
    self._send_output(message_body, encode_chunked=encode_chunked)
  File "/data/hyou37/anaconda3/envs/tinyml/lib/python3.7/http/client.py", line 1036, in _send_o
utput
    self.send(msg)
  File "/data/hyou37/anaconda3/envs/tinyml/lib/python3.7/http/client.py", line 976, in send
    self.connect()
  File "/data/hyou37/anaconda3/envs/tinyml/lib/python3.7/site-packages/urllib3/connection.py",
line 205, in connect
    conn = self._new_conn()
  File "/data/hyou37/anaconda3/envs/tinyml/lib/python3.7/site-packages/urllib3/connection.py",
line 187, in _new_conn
    self, "Failed to establish a new connection: %s" % e
urllib3.exceptions.NewConnectionError: <urllib3.connection.HTTPConnection object at 0x7f42a242e
a50>: Failed to establish a new connection: [Errno 111] Connection refused

During handling of the above exception, another exception occurred:

Traceback (most recent call last):
  File "/data/hyou37/anaconda3/envs/tinyml/lib/python3.7/site-packages/requests/adapters.py", l
ine 497, in send
    chunked=chunked,
  File "/data/hyou37/anaconda3/envs/tinyml/lib/python3.7/site-packages/urllib3/connectionpool.p
y", line 799, in urlopen
    method, url, error=e, _pool=self, _stacktrace=sys.exc_info()[2]
  File "/data/hyou37/anaconda3/envs/tinyml/lib/python3.7/site-packages/urllib3/util/retry.py",
line 592, in increment
    raise MaxRetryError(_pool, url, error or ResponseError(cause))
urllib3.exceptions.MaxRetryError: HTTPConnectionPool(host='localhost', port=9000): Max retries
exceeded with url: /api/v1/nni/experiment (Caused by NewConnectionError('<urllib3.connection.HT
TPConnection object at 0x7f42a242ea50>: Failed to establish a new connection: [Errno 111] Conne
ction refused'))

During handling of the above exception, another exception occurred:

Traceback (most recent call last):
  File "/data/hyou37/anaconda3/envs/tinyml/lib/python3.7/site-packages/nni/experiment/experimen
t.py", line 143, in _stop_impl
    rest.delete(self.port, '/experiment', self.url_prefix)
  File "/data/hyou37/anaconda3/envs/tinyml/lib/python3.7/site-packages/nni/experiment/rest.py",
 line 52, in delete
    request('delete', port, api, prefix=prefix)
  File "/data/hyou37/anaconda3/envs/tinyml/lib/python3.7/site-packages/nni/experiment/rest.py",
 line 31, in request
    resp = requests.request(method, url, timeout=timeout)
  File "/data/hyou37/anaconda3/envs/tinyml/lib/python3.7/site-packages/requests/api.py", line 5
9, in request
    return session.request(method=method, url=url, **kwargs)
  File "/data/hyou37/anaconda3/envs/tinyml/lib/python3.7/site-packages/requests/sessions.py", l
ine 589, in request
    resp = self.send(prep, **send_kwargs)
  File "/data/hyou37/anaconda3/envs/tinyml/lib/python3.7/site-packages/requests/sessions.py", l
ine 703, in send
    r = adapter.send(request, **kwargs)
  File "/data/hyou37/anaconda3/envs/tinyml/lib/python3.7/site-packages/requests/adapters.py", l
ine 519, in send
    raise ConnectionError(e, request=request)
requests.exceptions.ConnectionError: HTTPConnectionPool(host='localhost', port=9000): Max retri
es exceeded with url: /api/v1/nni/experiment (Caused by NewConnectionError('<urllib3.connection
.HTTPConnection object at 0x7f42a242ea50>: Failed to establish a new connection: [Errno 111] Co
nnection refused'))
[2023-09-15 02:55:12] WARNING: Cannot gracefully stop experiment, killing NNI process...
[2023-09-15 02:55:12] Experiment stopped
(tinyml) hyou37@eic-gt-gpu1:/data/hyou37/TinyML-Contest-Solution/Training$ python nni_nas.py
[2023-09-15 02:59:17] Creating experiment, Experiment ID: ahifk3o2
[2023-09-15 02:59:17] Starting web server...
[2023-09-15 02:59:18] Setting up...
[2023-09-15 02:59:18] Web portal URLs: http://127.0.0.1:9000 http://130.207.125.90:9000 http://
172.17.0.1:9000
node:events:504
      throw er; // Unhandled 'error' event
      ^

Error: tuner_command_channel: Tuner closed connection
    at WebSocket.handleWsClose (/data/hyou37/anaconda3/envs/tinyml/lib/python3.7/site-packages/
nni_node/core/tuner_command_channel/websocket_channel.js:83:26)
    at WebSocket.emit (node:events:538:35)
    at WebSocket.emitClose (/data/hyou37/anaconda3/envs/tinyml/lib/python3.7/site-packages/nni_
node/node_modules/express-ws/node_modules/ws/lib/websocket.js:246:10)
    at Socket.socketOnClose (/data/hyou37/anaconda3/envs/tinyml/lib/python3.7/site-packages/nni
_node/node_modules/express-ws/node_modules/ws/lib/websocket.js:1127:15)
    at Socket.emit (node:events:526:28)
    at TCP.<anonymous> (node:net:687:12)
Emitted 'error' event at:
    at WebSocketChannelImpl.handleError (/data/hyou37/anaconda3/envs/tinyml/lib/python3.7/site-
packages/nni_node/core/tuner_command_channel/websocket_channel.js:135:22)
    at WebSocket.handleWsClose (/data/hyou37/anaconda3/envs/tinyml/lib/python3.7/site-packages/
nni_node/core/tuner_command_channel/websocket_channel.js:83:14)
    at WebSocket.emit (node:events:538:35)
    [... lines matching original stack trace ...]
    at TCP.<anonymous> (node:net:687:12)
Thrown at:
    at handleWsClose (/data/hyou37/anaconda3/envs/tinyml/lib/python3.7/site-packages/nni_node/c
ore/tuner_command_channel/websocket_channel.js:83:26)
    at emit (node:events:538:35)
    at emitClose (/data/hyou37/anaconda3/envs/tinyml/lib/python3.7/site-packages/nni_node/node_
modules/express-ws/node_modules/ws/lib/websocket.js:246:10)
    at socketOnClose (/data/hyou37/anaconda3/envs/tinyml/lib/python3.7/site-packages/nni_node/n
ode_modules/express-ws/node_modules/ws/lib/websocket.js:1127:15)
    at emit (node:events:526:28)
    at node:net:687:12
Traceback (most recent call last):
  File "/data/hyou37/anaconda3/envs/tinyml/lib/python3.7/site-packages/urllib3/connection.py",
line 175, in _new_conn
    (self._dns_host, self.port), self.timeout, **extra_kw
  File "/data/hyou37/anaconda3/envs/tinyml/lib/python3.7/site-packages/urllib3/util/connection.
py", line 95, in create_connection
    raise err
  File "/data/hyou37/anaconda3/envs/tinyml/lib/python3.7/site-packages/urllib3/util/connection.
py", line 85, in create_connection
    sock.connect(sa)
ConnectionRefusedError: [Errno 111] Connection refused

During handling of the above exception, another exception occurred:

Traceback (most recent call last):
  File "/data/hyou37/anaconda3/envs/tinyml/lib/python3.7/site-packages/urllib3/connectionpool.p
y", line 721, in urlopen
    chunked=chunked,
  File "/data/hyou37/anaconda3/envs/tinyml/lib/python3.7/site-packages/urllib3/connectionpool.p
y", line 415, in _make_request
    conn.request(method, url, **httplib_request_kw)
  File "/data/hyou37/anaconda3/envs/tinyml/lib/python3.7/site-packages/urllib3/connection.py",
line 244, in request
    super(HTTPConnection, self).request(method, url, body=body, headers=headers)
  File "/data/hyou37/anaconda3/envs/tinyml/lib/python3.7/http/client.py", line 1281, in request
    self._send_request(method, url, body, headers, encode_chunked)
  File "/data/hyou37/anaconda3/envs/tinyml/lib/python3.7/http/client.py", line 1327, in _send_r
equest
    self.endheaders(body, encode_chunked=encode_chunked)
  File "/data/hyou37/anaconda3/envs/tinyml/lib/python3.7/http/client.py", line 1276, in endhead
ers
    self._send_output(message_body, encode_chunked=encode_chunked)
  File "/data/hyou37/anaconda3/envs/tinyml/lib/python3.7/http/client.py", line 1036, in _send_o
utput
    self.send(msg)
  File "/data/hyou37/anaconda3/envs/tinyml/lib/python3.7/http/client.py", line 976, in send
    self.connect()
  File "/data/hyou37/anaconda3/envs/tinyml/lib/python3.7/site-packages/urllib3/connection.py",
line 205, in connect
    conn = self._new_conn()
  File "/data/hyou37/anaconda3/envs/tinyml/lib/python3.7/site-packages/urllib3/connection.py",
line 187, in _new_conn
    self, "Failed to establish a new connection: %s" % e
urllib3.exceptions.NewConnectionError: <urllib3.connection.HTTPConnection object at 0x7fc9414ef
090>: Failed to establish a new connection: [Errno 111] Connection refused

During handling of the above exception, another exception occurred:

Traceback (most recent call last):
  File "/data/hyou37/anaconda3/envs/tinyml/lib/python3.7/site-packages/requests/adapters.py", l
ine 497, in send
    chunked=chunked,
  File "/data/hyou37/anaconda3/envs/tinyml/lib/python3.7/site-packages/urllib3/connectionpool.p
y", line 799, in urlopen
    method, url, error=e, _pool=self, _stacktrace=sys.exc_info()[2]
  File "/data/hyou37/anaconda3/envs/tinyml/lib/python3.7/site-packages/urllib3/util/retry.py",
line 592, in increment
    raise MaxRetryError(_pool, url, error or ResponseError(cause))
urllib3.exceptions.MaxRetryError: HTTPConnectionPool(host='localhost', port=9000): Max retries
exceeded with url: /api/v1/nni/check-status (Caused by NewConnectionError('<urllib3.connection.
HTTPConnection object at 0x7fc9414ef090>: Failed to establish a new connection: [Errno 111] Con
nection refused'))

During handling of the above exception, another exception occurred:

Traceback (most recent call last):
  File "nni_nas.py", line 83, in <module>
    experiment.run(port=9000)
  File "/data/hyou37/anaconda3/envs/tinyml/lib/python3.7/site-packages/nni/experiment/experimen
t.py", line 183, in run
    self._wait_completion()
  File "/data/hyou37/anaconda3/envs/tinyml/lib/python3.7/site-packages/nni/experiment/experimen
t.py", line 163, in _wait_completion
    status = self.get_status()
  File "/data/hyou37/anaconda3/envs/tinyml/lib/python3.7/site-packages/nni/experiment/experimen
t.py", line 283, in get_status
    resp = rest.get(self.port, '/check-status', self.url_prefix)
  File "/data/hyou37/anaconda3/envs/tinyml/lib/python3.7/site-packages/nni/experiment/rest.py",
 line 43, in get
    return request('get', port, api, prefix=prefix)
  File "/data/hyou37/anaconda3/envs/tinyml/lib/python3.7/site-packages/nni/experiment/rest.py",
 line 31, in request
    resp = requests.request(method, url, timeout=timeout)
  File "/data/hyou37/anaconda3/envs/tinyml/lib/python3.7/site-packages/requests/api.py", line 5
9, in request
    return session.request(method=method, url=url, **kwargs)
  File "/data/hyou37/anaconda3/envs/tinyml/lib/python3.7/site-packages/requests/sessions.py", l
ine 589, in request
    resp = self.send(prep, **send_kwargs)
  File "/data/hyou37/anaconda3/envs/tinyml/lib/python3.7/site-packages/requests/sessions.py", l
ine 703, in send
    r = adapter.send(request, **kwargs)
  File "/data/hyou37/anaconda3/envs/tinyml/lib/python3.7/site-packages/requests/adapters.py", l
ine 519, in send
    raise ConnectionError(e, request=request)
requests.exceptions.ConnectionError: HTTPConnectionPool(host='localhost', port=9000): Max retri
es exceeded with url: /api/v1/nni/check-status (Caused by NewConnectionError('<urllib3.connecti
on.HTTPConnection object at 0x7fc9414ef090>: Failed to establish a new connection: [Errno 111]
Connection refused'))
[2023-09-15 03:12:19] Stopping experiment, please wait...
[2023-09-15 03:12:19] ERROR: HTTPConnectionPool(host='localhost', port=9000): Max retries excee
ded with url: /api/v1/nni/experiment (Caused by NewConnectionError('<urllib3.connection.HTTPCon
nection object at 0x7fc951640a50>: Failed to establish a new connection: [Errno 111] Connection
 refused'))
Traceback (most recent call last):
  File "/data/hyou37/anaconda3/envs/tinyml/lib/python3.7/site-packages/urllib3/connection.py",
line 175, in _new_conn
    (self._dns_host, self.port), self.timeout, **extra_kw
  File "/data/hyou37/anaconda3/envs/tinyml/lib/python3.7/site-packages/urllib3/util/connection.
py", line 95, in create_connection
    raise err
  File "/data/hyou37/anaconda3/envs/tinyml/lib/python3.7/site-packages/urllib3/util/connection.
py", line 85, in create_connection
    sock.connect(sa)
ConnectionRefusedError: [Errno 111] Connection refused

During handling of the above exception, another exception occurred:

Traceback (most recent call last):
  File "/data/hyou37/anaconda3/envs/tinyml/lib/python3.7/site-packages/urllib3/connectionpool.p
y", line 721, in urlopen
    chunked=chunked,
  File "/data/hyou37/anaconda3/envs/tinyml/lib/python3.7/site-packages/urllib3/connectionpool.p
y", line 415, in _make_request
    conn.request(method, url, **httplib_request_kw)
  File "/data/hyou37/anaconda3/envs/tinyml/lib/python3.7/site-packages/urllib3/connection.py",
line 244, in request
    super(HTTPConnection, self).request(method, url, body=body, headers=headers)
  File "/data/hyou37/anaconda3/envs/tinyml/lib/python3.7/http/client.py", line 1281, in request
    self._send_request(method, url, body, headers, encode_chunked)
  File "/data/hyou37/anaconda3/envs/tinyml/lib/python3.7/http/client.py", line 1327, in _send_r
equest
    self.endheaders(body, encode_chunked=encode_chunked)
  File "/data/hyou37/anaconda3/envs/tinyml/lib/python3.7/http/client.py", line 1276, in endhead
ers
    self._send_output(message_body, encode_chunked=encode_chunked)
  File "/data/hyou37/anaconda3/envs/tinyml/lib/python3.7/http/client.py", line 1036, in _send_o
utput
    self.send(msg)
  File "/data/hyou37/anaconda3/envs/tinyml/lib/python3.7/http/client.py", line 976, in send
    self.connect()
  File "/data/hyou37/anaconda3/envs/tinyml/lib/python3.7/site-packages/urllib3/connection.py",
line 205, in connect
    conn = self._new_conn()
  File "/data/hyou37/anaconda3/envs/tinyml/lib/python3.7/site-packages/urllib3/connection.py",
line 187, in _new_conn
    self, "Failed to establish a new connection: %s" % e
urllib3.exceptions.NewConnectionError: <urllib3.connection.HTTPConnection object at 0x7fc951640
a50>: Failed to establish a new connection: [Errno 111] Connection refused

During handling of the above exception, another exception occurred:

Traceback (most recent call last):
  File "/data/hyou37/anaconda3/envs/tinyml/lib/python3.7/site-packages/requests/adapters.py", l
ine 497, in send
    chunked=chunked,
  File "/data/hyou37/anaconda3/envs/tinyml/lib/python3.7/site-packages/urllib3/connectionpool.p
y", line 799, in urlopen
    method, url, error=e, _pool=self, _stacktrace=sys.exc_info()[2]
  File "/data/hyou37/anaconda3/envs/tinyml/lib/python3.7/site-packages/urllib3/util/retry.py",
line 592, in increment
    raise MaxRetryError(_pool, url, error or ResponseError(cause))
urllib3.exceptions.MaxRetryError: HTTPConnectionPool(host='localhost', port=9000): Max retries
exceeded with url: /api/v1/nni/experiment (Caused by NewConnectionError('<urllib3.connection.HT
TPConnection object at 0x7fc951640a50>: Failed to establish a new connection: [Errno 111] Conne
ction refused'))

During handling of the above exception, another exception occurred:

Traceback (most recent call last):
  File "/data/hyou37/anaconda3/envs/tinyml/lib/python3.7/site-packages/nni/experiment/experimen
t.py", line 143, in _stop_impl
    rest.delete(self.port, '/experiment', self.url_prefix)
  File "/data/hyou37/anaconda3/envs/tinyml/lib/python3.7/site-packages/nni/experiment/rest.py",
 line 52, in delete
    request('delete', port, api, prefix=prefix)
  File "/data/hyou37/anaconda3/envs/tinyml/lib/python3.7/site-packages/nni/experiment/rest.py",
 line 31, in request
    resp = requests.request(method, url, timeout=timeout)
  File "/data/hyou37/anaconda3/envs/tinyml/lib/python3.7/site-packages/requests/api.py", line 5
9, in request
    return session.request(method=method, url=url, **kwargs)
  File "/data/hyou37/anaconda3/envs/tinyml/lib/python3.7/site-packages/requests/sessions.py", l
ine 589, in request
    resp = self.send(prep, **send_kwargs)
  File "/data/hyou37/anaconda3/envs/tinyml/lib/python3.7/site-packages/requests/sessions.py", l
ine 703, in send
    r = adapter.send(request, **kwargs)
  File "/data/hyou37/anaconda3/envs/tinyml/lib/python3.7/site-packages/requests/adapters.py", l
ine 519, in send
    raise ConnectionError(e, request=request)
requests.exceptions.ConnectionError: HTTPConnectionPool(host='localhost', port=9000): Max retri
es exceeded with url: /api/v1/nni/experiment (Caused by NewConnectionError('<urllib3.connection
.HTTPConnection object at 0x7fc951640a50>: Failed to establish a new connection: [Errno 111] Co
nnection refused'))
[2023-09-15 03:12:19] WARNING: Cannot gracefully stop experiment, killing NNI process...
[2023-09-15 03:12:19] Experiment stopped
(tinyml) hyou37@eic-gt-gpu1:/data/hyou37/TinyML-Contest-Solution/Training$
